Workbook

Sheet Dashboard
A1: Habio launch QA checklist — dashboard
A3: How to use this workbook
A4: - Each tab (Customer App, Professional App, Backend & Shared Logic) lists every screen or piece of logic built so far, grouped the way the app actually flows.
A5: - Set the Status column as you confirm what state something is really in: Not Built, Built - Not Tested, Deployed - Not Tested, or Deployed and Confirmed.
A6: - Set the Tested? column as you physically walk through each screen on a device: Not Started, In Progress, Pass, or Fail.
A7: - Priority flags what should block launch (Launch Blocker) vs what can slip (High / Medium / Low). Adjust freely - the starting values are a judgment call based on the engineering log.
A8: - Use Notes / issues found to record anything broken, half-working, or needing a follow-up decision from you.
A9: - The counts below update automatically from all three sheets as you edit the Status column.
A11: Status counts across all three sheets
A12: Status | B12: Customer App | C12: Professional App | D12: Backend & Shared Logic | E12: Total
A13: Not Built | B13: =COUNTIF('Customer App'!D:D,A13) -> 8 | C13: =COUNTIF('Professional App'!D:D,A13) -> 10 | D13: =COUNTIF('Backend & Shared Logic'!D:D,A13) -> 0 | E13: =SUM(B13:D13) -> 18
A14: Built - Not Tested | B14: =COUNTIF('Customer App'!D:D,A14) -> 9 | C14: =COUNTIF('Professional App'!D:D,A14) -> 2 | D14: =COUNTIF('Backend & Shared Logic'!D:D,A14) -> 4 | E14: =SUM(B14:D14) -> 15
A15: Deployed - Not Tested | B15: =COUNTIF('Customer App'!D:D,A15) -> 1 | C15: =COUNTIF('Professional App'!D:D,A15) -> 15 | D15: =COUNTIF('Backend & Shared Logic'!D:D,A15) -> 3 | E15: =SUM(B15:D15) -> 19
A16: Deployed and Confirmed | B16: =COUNTIF('Customer App'!D:D,A16) -> 18 | C16: =COUNTIF('Professional App'!D:D,A16) -> 11 | D16: =COUNTIF('Backend & Shared Logic'!D:D,A16) -> 10 | E16: =SUM(B16:D16) -> 39
A17: Total items | B17: =SUM(B13:B16) -> 36 | C17: =SUM(C13:C16) -> 38 | D17: =SUM(D13:D16) -> 17 | E17: =SUM(E13:E16) -> 91
A19: Launch blocker count by sheet
A20: Sheet | B20: Launch Blockers (any status) | C20: Launch Blockers still Not Built or Not Tested
A21: Customer App | B21: =COUNTIF('Customer App'!F:F,"Launch Blocker") -> 9 | C21: =COUNTIFS('Customer App'!F:F,"Launch Blocker",'Customer App'!D:D,"Not Built")+COUNTIFS('Customer App'!F:F,"Launch Blocker",'Customer App'!D:D,"Built - Not Tested")+COUNTIFS('Customer App'!F:F,"Launch Blocker",'Customer App'!D:D,"Deployed - Not Tested") -> 9
A22: Professional App | B22: =COUNTIF('Professional App'!F:F,"Launch Blocker") -> 5 | C22: =COUNTIFS('Professional App'!F:F,"Launch Blocker",'Professional App'!D:D,"Not Built")+COUNTIFS('Professional App'!F:F,"Launch Blocker",'Professional App'!D:D,"Built - Not Tested")+COUNTIFS('Professional App'!F:F,"Launch Blocker",'Professional App'!D:D,"Deployed - Not Tested") -> 5
A23: Backend & Shared Logic | B23: =COUNTIF('Backend & Shared Logic'!F:F,"Launch Blocker") -> 7 | C23: =COUNTIFS('Backend & Shared Logic'!F:F,"Launch Blocker",'Backend & Shared Logic'!D:D,"Not Built")+COUNTIFS('Backend & Shared Logic'!F:F,"Launch Blocker",'Backend & Shared Logic'!D:D,"Built - Not Tested")+COUNTIFS('Backend & Shared Logic'!F:F,"Launch Blocker",'Backend & Shared Logic'!D:D,"Deployed - Not Tested") -> 2
A25: Last reviewed 2026-09-08 by Claude -- statuses cross-checked against this week's engineering session (App Check fix, request-data-completeness fix, availability re-match addition) and the project's master to-do / engineering log. Adjust anything that doesn't match what you're actually seeing.

Sheet Sheet

Sheet Customer App
A1: Habio launch QA checklist — Customer App
A2: Section | B2: Screen / Feature | C2: What it does | D2: Status | E2: Tested? | F2: Priority | G2: Notes / issues found
A3: Entry
B4: Splash screen | C4: Standard timing splash, cityscape decoration, logo. | D4: Deployed and Confirmed | E4: Pass | F4: Low
B5: Onboarding carousel (3 pages) | C5: Handshake / describe-problem / completed-service illustrated pages, shown once before login. | D5: Deployed and Confirmed | E5: Not Started | F5: Medium
B6: Login / OTP screen | C6: Phone entry + OTP verify. Logo enlarged 70x70 to 100x100. | D6: Deployed and Confirmed | E6: Pass | F6: Medium | G6: OTP login itself has been used continuously throughout testing -- every other confirmed flow (bidding, chat, cancellation) depends on being logged in, so this is clearly working. The specific 100x100 logo resize hasn't been separately visually confirmed.
A7: Home screen
B8: Quick Services section | C8: 2-card row for Cleaning + Helper Services with Fixed price badge, routes into tier-based flow. | D8: Built - Not Tested | E8: Not Started | F8: Launch Blocker
B9: Browse Categories grid | C9: All 15 non-quick categories, filters out the 2 Quick Services categories. | D9: Built - Not Tested | E9: Not Started | F9: Launch Blocker
B10: Trending Services | C10: Currently inactive placeholder, no real logic or Firestore wiring yet. | D10: Not Built | E10: Not Started | F10: Medium
B11: Emergency / Night Services | C11: Currently inactive placeholder, scope not yet defined. | D11: Not Built | E11: Not Started | F11: Medium
B12: Frequently Used section | C12: Existing, already-live widget, untouched by recent work. | D12: Deployed and Confirmed | E12: Not Started | F12: Low
A13: Standard request flow (15 bidding categories)
B14: Category -> Subcategory screen | C14: Subcategory picker; 4 categories (Metal Fab, Glass, Fabric, Decoration) newly added, needs a fresh build to appear. | D14: Built - Not Tested | E14: Not Started | F14: Launch Blocker
B15: Add request details | C15: Free-text / structured details for the job. | D15: Deployed and Confirmed | E15: Not Started | F15: Low
B16: Confirm location screen | C16: Address capture and pin confirmation. | D16: Deployed and Confirmed | E16: Not Started | F16: Low
B17: Date / time screen | C17: 24 specific 1-hour slots plus Anytime, replacing old Morning/Afternoon/Evening buckets. Shared by every category. | D17: Built - Not Tested | E17: Not Started | F17: Launch Blocker
B18: Review & Submit screen | C18: Shows 'Request Quotes' CTA for bidding requests. | D18: Deployed and Confirmed | E18: Not Started | F18: Medium | G18: 2026-09-08: fixed a bug where category/subcategory/address/date/time-slot were silently dropped when the request was written to Firestore (a gap between the ServiceRequest and ServiceRequestModel classes) -- the professional's opportunity card was showing incomplete details as a result. Fix committed to request_service.dart/request_repository.dart/finding_professionals_screen.dart; needs a fresh end-to-end request to confirm the professional now sees full details.
B19: Finding Professionals (bidding copy) | C19: Transition screen with quotation-oriented copy. | D19: Deployed and Confirmed | E19: Not Started | F19: Low
B20: Bid list screen | C20: Real Firestore bid stream, compare bids, accept a bid. | D20: Deployed and Confirmed | E20: Not Started | F20: High
A21: Quick Services request flow (Cleaning + Helper Services)
B22: Fixed-price request screen (tier picker) | C22: 3 tiers per subcategory across all 32 subcategories, 96 placeholder prices need review. | D22: Built - Not Tested | E22: Not Started | F22: Launch Blocker
B23: Address screen (reused) | C23: Same AddressScreen as bidding flow, unmodified. | D23: Deployed and Confirmed | E23: Not Started | F23: Low
B24: Review & Submit (fixed-price copy) | C24: Shows 'Submit Request' CTA instead of Request Quotes. | D24: Deployed and Confirmed | E24: Not Started | F24: Medium
B25: Finding Professionals (fixed-price copy) | C25: Conditional copy: 'price already set, waiting for acceptance'. | D25: Built - Not Tested | E25: Not Started | F25: Medium
B26: Fixed Price Waiting screen | C26: Raise-price bottom sheet, 45-second 'taking longer than usual' banner. | D26: Built - Not Tested | E26: Not Started | F26: Launch Blocker
A27: Order lifecycle (shared)
B28: Order Status screen | C28: Confirmed / active / completed states, professional contact card. | D28: Deployed and Confirmed | E28: Not Started | F28: High
B29: Cancellation flow (payment-gated redesign) | C29: cancelOrder only records intent; order stays active until payCancellationFee actually clears it. | D29: Deployed - Not Tested | E29: Not Started | F29: Launch Blocker | G29: Backend functions (cancelOrder, payCancellationFee) were redeployed 2026-09-08 alongside the App Check fix, so the full loop can now actually be tested end-to-end -- that walkthrough hasn't happened yet.
B30: Cancellation fee payment sheet (mocked) | C30: Ppay 150 rupees mock sheet, already confirmed working by Harsh once. | D30: Deployed and Confirmed | E30: Pass | F30: Medium
B31: Rate & Review screen | C31: One review per completed order, immutable once submitted. | D31: Deployed and Confirmed | E31: Not Started | F31: Low
A32: Bookings tab
B33: Ongoing / Completed / Cancelled tabs | C33: Three-stage bookings list. | D33: Deployed and Confirmed | E33: Not Started | F33: Medium
B34: Upcoming card routing fix | C34: Fixed-price requests now route to Waiting screen instead of the bid list. | D34: Built - Not Tested | E34: Not Started | F34: High
B35: Pay button swap on pending fee | C35: Card button switches Cancel -> Pay 150 rupees while a fee is pending. | D35: Deployed and Confirmed | E35: Not Started | F35: Low
A36: Profile / support
B37: Support chat (customer to admin) | C37: Confirmed end to end, admin replies via standalone console. | D37: Deployed and Confirmed | E37: Pass | F37: Low
B38: Public professional profile view | C38: Ratings, completed jobs count, review history, portfolio photos. | D38: Deployed and Confirmed | E38: Not Started | F38: Low
A39: Not yet built (customer side)
B40: Live GPS tracking | C40: En-route / on-the-way map view of the assigned professional. | D40: Not Built | E40: Not Started | F40: High
...

Sheet Professional App
A1: Habio launch QA checklist — Professional App
A2: Section | B2: Screen / Feature | C2: What it does | D2: Status | E2: Tested? | F2: Priority | G2: Notes / issues found
A3: Entry
B4: Splash screen | C4: Cityscape decoration matching customer app, 5-second timing. | D4: Deployed and Confirmed | E4: Pass | F4: Low
B5: Post-splash intro carousel | C5: Overhauled 2026-09-04 to use real mascot artwork (price-setting / matched-jobs / earnings) replacing the earlier code-drawn character. | D5: Deployed - Not Tested | E5: Not Started | F5: Medium | G5: Shipped as part of the professional app's real release build (~2026-09-06/07, the ~74MB release APK); not separately walked through on-device.
B6: Login / OTP screen | C6: Phone entry + OTP verify, separate file from the customer app's OTP screen. | D6: Deployed and Confirmed | E6: Pass | F6: Low
A7: Onboarding wizard
B8: Name / about / experience step | C8: Basic profile fields. | D8: Deployed and Confirmed | E8: Not Started | F8: Low
B9: Category + subcategory picker | C9: Mirrored taxonomy; needs rebuild to show the 4 newly added categories. | D9: Deployed - Not Tested | E9: Not Started | F9: Launch Blocker | G9: Shipped in the professional app's real release build -- the rebuild this needed has happened. Not yet visually confirmed that all 4 new categories (Metal Fabrication, Glass Work, Fabric & Tailoring, Decoration & Events) actually appear.
B10: Business vs Individual choice | C10: Business path requires GST number plus certificate upload; raises active-order cap to 5 and adds an Employee Assigned field on bids. | D10: Deployed - Not Tested | E10: Not Started | F10: Medium | G10: Shipped in the same release build as the category picker rebuild above.
B11: Service area + location + radius step | C11: Geolocator-based capture, configurable service radius. | D11: Deployed and Confirmed | E11: Not Started | F11: Low
B12: Optional referral-code entry | C12: New field on VerificationScreen, resolved against referral_codes collection. | D12: Built - Not Tested | E12: Not Started | F12: Medium | G12: Client-side field is shipped in the release build, but resolving a code depends on firestore.rules for the new referral_codes collection -- that rules deploy (firebase deploy --only firestore:rules) hasn't been confirmed run yet, so entering a code may currently fail with a permission error. Test only after that deploy.
B13: Verification screen (document upload) | C13: PAN / Aadhaar / bank statement / photo upload. isVerified is still an auto-true placeholder. | D13: Deployed and Confirmed | E13: Not Started | F13: Medium
A14: Professional home
B15: Welcome header with real name | C15: Fixed from a hardcoded 'Welcome to Habio' string. | D15: Deployed - Not Tested | E15: Not Started | F15: Medium | G15: Shipped in the release build; not separately confirmed the header shows the real name rather than the old hardcoded string.
B16: Service location chip | C16: Now defaults to the professional's real registered area instead of a hardcoded city. | D16: Deployed - Not Tested | E16: Not Started | F16: Medium | G16: Shipped in the release build; not separately confirmed.
B17: Bell + Requests tab badge | C17: Counts outstanding SENT opportunities directly, not the notifications list. | D17: Deployed and Confirmed | E17: Not Started | F17: Low
B18: Referral popup (once per app open) | C18: Closeable via top-right X, links to the shared Refer & Earn screen. | D18: Deployed - Not Tested | E18: Not Started | F18: Medium | G18: Shipped in the release build; not separately confirmed the popup only fires once per app open.
A19: Opportunities
B20: Standard bid opportunity + submission | C20: Accept/Ignore card leads into full bid composition (price, materials, warranty etc). | D20: Deployed and Confirmed | E20: Pass | F20: High | G20: 2026-09-08: the customer-side data-completeness fix (category/address/date/time-slot no longer dropped on submit -- see Customer App sheet) means bid opportunity cards should now show full request details; not yet re-confirmed live since that fix.
B21: Fixed-price opportunity card | C21: Accept or Ignore only, shows tier label and below-floor warning. | D21: Deployed - Not Tested | E21: Not Started | F21: Launch Blocker | G21: Shipped in the release build. Also benefits from the 2026-09-08 customer-side data-completeness fix for the tier label / full details. Not yet walked through live.
B22: First-to-accept-wins race guard | C22: Transaction throws already-exists for the second professional to accept. | D22: Deployed - Not Tested | E22: Not Started | F22: Launch Blocker | G22: The Cloud Function transaction logic this depends on was redeployed 2026-09-08 alongside the App Check fix (a full firebase deploy --only functions was run). The actual race-condition test (two professionals accepting at once) still hasn't been attempted.
A23: Job execution
B24: Job Details screen (real) | C24: Streams the real order, Start Job / Complete Job call real Cloud Functions. | D24: Deployed and Confirmed | E24: Pass | F24: High
B25: accepted_job_screen.dart (orphaned mock) | C25: Dead code, never navigated to. Decide: leave or delete. | D25: Not Built | E25: Not Started | F25: Low
B26: Withdraw from Job (150 rupee fee) | C26: Auto-deducted from wallet, order re-matched to other professionals. | D26: Deployed and Confirmed | E26: Not Started | F26: High
B27: Job completion photos | C27: 1 to 3 mandatory photos, enforced server-side, feeds public portfolio. | D27: Deployed and Confirmed | E27: Not Started | F27: Low
B28: In-job pickup escalation (Automobile / Appliances) | C28: Condition photos + OTP at pickup and delivery, 5-state sub-status chain. Rare exception path. | D28: Not Built | E28: Not Started | F28: Medium
A29: Wallet / earnings
B30: Earnings screen | C30: Wired to real wallet_ledger; shows completed jobs, withdrawal-fee entries, referral-commission entries. | D30: Deployed - Not Tested | E30: Not Started | F30: High | G30: Client is in the release build; the wallet-crediting Cloud Functions it depends on (completeJob, referral commission) were redeployed 2026-09-08. Not yet walked through live.
B31: Instant payout for orders >= 5000 rupees + WhatsApp PDF | C31: Explicitly deferred trust-building feature. | D31: Not Built | E31: Not Started | F31: Low
A32: Profile tab
B33: My Skills | C33: Reads/writes real subcategoryIds against the real taxonomy, replacing an unrelated hardcoded list. | D33: Deployed - Not Tested | E33: Not Started | F33: Launch Blocker | G33: Shipped in the release build; not separately confirmed on-device.
B34: Personal Details | C34: Real name/about/email prefilled, phone shown read-only. | D34: Deployed - Not Tested | E34: Not Started | F34: Medium | G34: Shipped in the release build; not separately confirmed on-device.
B35: Verification Status (new, read-only) | C35: Shows real document/verified status without forcing re-upload. | D35: Deployed - Not Tested | E35: Not Started | F35: Medium | G35: Shipped in the release build; not separately confirmed on-device.
B36: Service Area (rebuilt) | C36: Normal Profile-subscreen chrome, real location/radius prefill, use-current-location action. | D36: Deployed - Not Tested | E36: Not Started | F36: Launch Blocker | G36: Shipped in the release build; not separately confirmed on-device.
B37: Profile completeness percentage | C37: Now computed from 5 real checks instead of a hardcoded 80 percent; weighting is a judgment call worth reviewing. | D37: Deployed - Not Tested | E37: Not Started | F37: Low | G37: Shipped in the release build; not separately confirmed on-device.
B38: Refer & Earn screen | C38: Code display/share, reward explanation, stats, referred-professionals list. | D38: Built - Not Tested | E38: Not Started | F38: Medium | G38: Same firestore.rules dependency as the referral-code entry above (row 12) -- the referred-professionals list / stats query may fail until that rules deploy runs.
B39: My Reviews screen | C39: Average rating, completed jobs, full review list. | D39: Deployed and Confirmed | E39: Not Started | F39: Low
A40: Conduct / training (onboarding gate)
...

Sheet Backend & Shared Logic
A1: Habio launch QA checklist — Backend & Shared Logic
A2: Section | B2: Screen / Feature | C2: What it does | D2: Status | E2: Tested? | F2: Priority | G2: Notes / issues found
A3: Matching & bidding
B4: matchProfessionalsToRequest engine | C4: Core eligible-professional search + opportunity fan-out. Untouched through every recent change. | D4: Deployed and Confirmed | E4: Pass | F4: Launch Blocker
B5: Bid pipeline (bid_service.dart, opportunity docs) | C5: Bids stored as fields on the opportunity doc, not a separate collection. | D5: Deployed and Confirmed | E5: Pass | F5: High
A6: Order lifecycle Cloud Functions
B7: acceptBid / acceptFixedPriceOpportunity | C7: Creates the order doc, closes other opportunities, increments activeOrderCount. | D7: Deployed and Confirmed | E7: Pass | F7: Launch Blocker | G7: Confirmed working 2026-09-08 -- this was the function behind the 'Accept job' Unauthenticated bug; fixed by disabling App Check enforcement (see row below) and confirmed working afterward.
B8: startJob / completeJob | C8: Status transitions, mandatory completion photos, commission + referral crediting. | D8: Deployed and Confirmed | E8: Pass | F8: Launch Blocker
B9: cancelOrder / payCancellationFee (redesigned) | C9: Payment-gated split: order stays active until the fee is actually paid. | D9: Deployed - Not Tested | E9: Not Started | F9: Launch Blocker | G9: Deployed via the 2026-09-08 firebase deploy --only functions run (done alongside the App Check fix) -- the earlier 'needs a deploy' blocker is cleared. Not yet live-tested.
B10: professionalWithdrawOrder | C10: Atomic withdrawal + re-match to other eligible professionals. | D10: Deployed and Confirmed | E10: Not Started | F10: High
B11: raiseFixedPriceOrder | C11: Customer-initiated price raise, re-broadcasts via the existing matching function. | D11: Deployed and Confirmed | E11: Pass | F11: High | G11: This was the function behind the 'Raise price' Unauthenticated bug reported 2026-09-08 -- fixed by disabling App Check enforcement and confirmed working afterward ('Now it works').
B12: Referral commission crediting (in completeJob) | C12: 1 percent of job fees excluding materials, credited to referrer, gated on 1-year window. | D12: Deployed - Not Tested | E12: Not Started | F12: Medium | G12: Deployed via the same 2026-09-08 functions deploy. Still needs firebase deploy --only firestore:rules for the referral_codes rules before a real end-to-end referral test (two accounts) is possible.
A13: Notifications & support
B14: createNotification on lifecycle events | C14: New opportunity, bid accepted/submitted, job started/completed, payment, review, cancellation. | D14: Deployed and Confirmed | E14: Pass | F14: Medium
B15: Support chat + admin console | C15: Standalone HTML admin tool, confirmed working end to end. | D15: Deployed and Confirmed | E15: Pass | F15: Low
A16: Security & infra
B17: Firestore rules (referral_codes, collection-group, admin gate) | C17: Latest additions not yet deployed. | D17: Built - Not Tested | E17: Not Started | F17: Launch Blocker | G17: Needs firebase deploy --only firestore:rules. Still not deployed as of 2026-09-08 -- this is now the one blocker on the referral program actually working end-to-end (see the two rows above).
B18: App Check enforcement (9 callable functions) | C18: Code shipped with enforceAppCheck true on every callable function. | D18: Deployed and Confirmed | E18: Pass | F18: Launch Blocker | G18: Reversed 2026-09-08: enforceAppCheck was deliberately flipped from true to false on all 9 callable functions, because Play Integrity only validates a Play-Store-installed app and both apps are still sideloaded with no Play Console account yet -- with it left on, every one of these calls was failing before it even reached the function body, surfacing as a bare 'Unauthenticated' error. This change was deployed and confirmed to fix Accept Job / Raise Price. Re-enable once the company's Play Console account is registered (needs a D-U-N-S number) and the app is installed via its Internal Testing track -- this condition is saved to memory, not due yet.
B19: Android code shrinking + obfuscation (R8/ProGuard) | C19: Release build minify + resource shrink turned on both apps. | D19: Deployed - Not Tested | E19: In Progress | F19: High | G19: Needs one real release build + full smoke test. The professional app's real release build (~2026-09-06/07) uses this build config (R8/ProGuard minify+shrink is the standard release setting). Core flows built on it (accept bid, raise price) have worked fine post-build, so nothing critical has broken so far -- but no dedicated full smoke test has been done yet.
B20: Dart obfuscation (build_release.bat) | C20: Obfuscated app bundle build script; symbols folder must be stored privately per release. | D20: Built - Not Tested | E20: Not Started | F20: Medium | G20: The professional release APK built this week used a plain flutter build apk --release, not build_release.bat -- so Dart obfuscation specifically was NOT applied to that build. Still needs a build via the obfuscation script to actually test this item.
B21: Maps API key out of plaintext manifest | C21: Moved to gitignored secrets.properties per app. | D21: Built - Not Tested | E21: Not Started | F21: Medium | G21: Still needs SHA-1 restriction on the key in Google Cloud Console.
A22: Data state
B23: Firestore fully wiped (2026-09-04 reset) | C23: No registered professionals, requests, orders, reviews, or wallet balances currently exist. | D23: Deployed and Confirmed | E23: Not Started | F23: Launch Blocker | G23: Every test above needs fresh signups first. A further reset appears to have been requested again in early September (the same firebase firestore:delete --recursive --force instructions as the 2026-09-04 wipe, to be run by Harsh himself) -- not explicitly confirmed done in chat, but the professional app showing zero active opportunities during this week's testing is consistent with it having been carried out. Worth a quick confirmation.
A25: Additions since last QA pass (2026-09-08)
B26: onProfessionalAvailabilityChanged (re-match on availability ON) | C26: Previously, matching only ran once at request creation -- a professional toggled off when a request came in would never see it, even after toggling back on. New Cloud Function fires when a professional's isAvailable flips to true and fans out fresh opportunities for every still-open request they're eligible for (same capability/category/radius rules as the original matching engine), skipping anything they've already been shown or that's already been awarded. | D26: Built - Not Tested | E26: Not Started | F26: High | G26: Added 2026-09-08 per Harsh's report. Needs firebase deploy --only functions, then a live test: toggle a professional off, submit a matching request as a customer, toggle the professional back on, confirm the request appears on their Requests tab within a few seconds.
